<?xml version="1.0"?>
<robot xmlns:xacro="http://www.ros.org/wiki/xacro"> 
	
	
	<xacro:include filename="$(find rb2_description)/urdf/elevator/elevator.transmission.xacro"/>
	<xacro:include filename="$(find rb2_description)/urdf/elevator/elevator.gazebo.xacro"/>
	
	<xacro:macro name="elevator_platform" params="prefix parent hq *origin">
	<!-- PARAMS: -->
	<!-- name : name of the link: -->
	<!-- hq: selects model in high quality (.dae) -->


   <xacro:macro name="solid_cuboid_inertia" params="m h d w">
    <inertia  ixx="${(m*(h*h+d*d))/12}" ixy = "0" ixz = "0"
              iyy="${(m*(w*w+d*d))/12}" iyz = "0"
              izz="${(m*(w*w+h*h))/12}"
     /> 
  </xacro:macro>

	<!-- ELEVATOR PLATFORM -->
	<joint name="${prefix}_platform_joint" type="prismatic">
			<origin xyz="0.0 0.0 0.285" rpy="0 0 0 " />
			<parent link="${parent}"/>
			<child link="${prefix}_platform_link" />
			<axis xyz="0 0 1"/>
			<limit effort="100.0" lower="0.0" upper="0.05" velocity="0.5"/>
			<dynamics damping="0.7"/>
	</joint> 
	<link name="${prefix}_platform_link">
		<visual>
			<origin xyz="0 0 0" rpy="0 0 0" />
			<xacro:if value="${hq}">
				<geometry>
					<mesh filename="package://rb2_description/meshes/elevator/rb2_elevator.dae"/>
				</geometry>
			</xacro:if>
			<xacro:unless value="${hq}">
				<geometry>
					<mesh filename="package://rb2_description/meshes/elevator/rb2_elevator.stl"/>
				</geometry>
			</xacro:unless>
			<material name="black">
				<color rgba="0.0 0.0 0.0 1"/>
			</material>
		</visual>  
		<collision>
			<origin xyz="0 0 0" rpy="0 0 0 " />
			<geometry>
				<mesh filename="package://rb2_description/meshes/elevator/rb2_elevator.dae"/>
			</geometry>
		</collision>
		<inertial>
			<mass value="0.05" />
			<origin xyz="0 0 -0.27" />
			<solid_cuboid_inertia m="0.05" h="0.05" d="0.05" w="0.05"/>
		</inertial> 
	</link>

	<xacro:elevator_transmission prefix="${prefix}" />
	<xacro:elevator_gazebo prefix="${prefix}" />

	</xacro:macro>
	

	
</robot>

