<?xml version="1.0"?>
<robot xmlns:xacro="http://www.ros.org/wiki/xacro"> 
	
	
	<xacro:include filename="$(find rb2_description)/urdf/elevator/elevator.transmission.xacro"/>
	<xacro:include filename="$(find rb2_description)/urdf/elevator/elevator.gazebo.xacro"/>
	
	<xacro:macro name="elevator_platform" params="prefix parent hq *origin">
	<!-- PARAMS: -->
	<!-- name : name of the link: -->
	<!-- hq: selects model in high quality (.dae) -->

	<!-- ELEVATOR PLATFORM -->
	<joint name="${prefix}_elevator_joint" type="prismatic">
			<origin xyz="0.0 0.0 0.285" rpy="0 0 0 " />
			<parent link="${parent}"/>
			<child link="${prefix}_elevator_link" />
			<axis xyz="0 0 1"/>
			<limit effort="1.0" lower="0.0" upper="0.06" velocity="0.5"/>
	</joint> 
	<link name="${prefix}_elevator_link">
		<visual>
			<origin xyz="0 0 0" rpy="0 0 0" />
			<xacro:if value="${hq}">
				<geometry>
					<mesh filename="package://rb2_description/meshes/elevator/rb2_elevator.dae"/>
				</geometry>
			</xacro:if>
			<xacro:unless value="${hq}">
				<geometry>
					<mesh filename="package://rb2_description/meshes/elevator/rb2_elevator.stl"/>
				</geometry>
			</xacro:unless>
			<material name="black">
				<color rgba="0.0 0.0 0.0 1"/>
			</material>
		</visual>  
		<collision>
			<origin xyz="0 0 0" rpy="0 0 0 " />
			<geometry>
				<mesh filename="package://rb2_description/meshes/elevator/rb2_elevator.dae"/>
			</geometry>
		</collision>
	</link>

	<!--xacro:elevator_transmission prefix="${prefix}" />
	<xacro:elevator_gazebo prefix="${prefix}" /-->

	</xacro:macro>
	

	
</robot>

